<?xml version="1.0"?> <!--Necessary line to declare this is a xml file -->
<!-- If you put two links and do not specify the relation or which one is the root(parent) that will cause errors -->
<robot name="my_robot"> 
<!-- Write everyting related to the robot inside here -->
    <material name="blue">
        <color rgba="0 0 0.5 1" /> <!-- Define the color of the material rgba = red/green/blue/alpha, alpha = transparency -->
    </material>
    
    <material name="grey">
        <color rgba="0.5 0.5 0.5 1" />
    </material>

    <material name="green">
        <color rgba="0 0.5 0 1" />
    </material>

    <link name="base_footprint" />

    <link name="base_link"> <!-- Define the base link of the robot MUST DO IT EVERYTIME-->
        <visual> <!-- Define the visual properties of the link -->
            <geometry> <!-- Define the geometry of the link -->
                <box size="0.6 0.4 0.2" /> <!-- Define the size of the box -->
            </geometry>
            <origin xyz="0 0 0.1" rpy="0 0 0"/> <!-- Define the position and orientation of the box rpy = roll/pitch/yaw = x/y/z rotation This line is after geometry-->
            <!-- 0.1 is due to box being below the surface in RVIZ we must shift it upwards-->
            <material name="blue" /> <!-- Define the material of the box -->
        </visual>
    </link>

    <link name="right_wheel_link">
        <visual>
            <geometry>
                <cylinder radius="0.1" length="0.05" />
            </geometry>
            <origin xyz="0 0 0" rpy="1.57 0 0" />
            <material name="grey" />
        </visual>
    </link>

    <link name="left_wheel_link">
        <visual>
            <geometry>
                <cylinder radius="0.1" length="0.05" />
            </geometry>
            <origin xyz="0 0 0" rpy="1.57 0 0" />
            <material name="grey" />
        </visual>
    </link>

    <link name="caster_wheel_link">
        <visual>
            <geometry>
                <sphere radius="0.05" />
            </geometry>
            <origin xyz="0 0 0" rpy="0 0 0" />
            <material name="grey" />
        </visual>
    </link>

    <joint name="base_joint" type="fixed">
        <parent link="base_footprint" />
        <child link="base_link" />
        <origin xyz="0 0 0.1" rpy="0 0 0" />
    </joint>

    <joint name="base_right_wheel_joint" type="continuous">
        <parent link="base_link" />
        <child link="right_wheel_link" />
        <origin xyz="-0.15 -0.225 0" rpy="0 0 0" />
        <axis xyz="0 1 0" />
    </joint>

    <joint name="base_left_wheel_joint" type="continuous">
        <parent link="base_link" />
        <child link="left_wheel_link" />
        <origin xyz="-0.15 0.225 0" rpy="0 0 0" />
        <axis xyz="0 1 0" />
    </joint>

    <joint name="base_caster_wheel_joint" type="fixed">
        <parent link="base_link" />
        <child link="caster_wheel_link" />
        <origin xyz="0.2 0 -0.05" rpy="0 0 0" />
    </joint>



</robot>
